<sdf version='1.6'>
  <world name='autonomous_landing'>
    <light name='sun' type='directional'>
      <cast_shadows>1</cast_shadows>
      <pose frame=''>0 0 10 0 -0 0</pose>
      <diffuse>0.8 0.8 0.8 1</diffuse>
      <specular>0.2 0.2 0.2 1</specular>
      <attenuation>
        <range>1000</range>
        <constant>0.9</constant>
        <linear>0.01</linear>
        <quadratic>0.001</quadratic>
      </attenuation>
      <direction>-0.5 0.1 -0.9</direction>
    </light>
    <model name='ground_plane'>
      <static>1</static>
      <link name='link'>
        <collision name='collision'>
          <geometry>
            <plane>
              <normal>0 0 1</normal>
              <size>100 100</size>
            </plane>
          </geometry>
          <surface>
            <friction>
              <ode>
                <mu>100</mu>
                <mu2>50</mu2>
              </ode>
              <torsional>
                <ode/>
              </torsional>
            </friction>
            <contact>
              <ode/>
            </contact>
            <bounce/>
          </surface>
          <max_contacts>10</max_contacts>
        </collision>
        <visual name='visual'>
          <cast_shadows>0</cast_shadows>
          <geometry>
            <plane>
              <normal>0 0 1</normal>
              <size>100 100</size>
            </plane>
          </geometry>
          <material>
            <script>
              <uri>file://media/materials/scripts/gazebo.material</uri>
              <name>Gazebo/Grey</name>
            </script>
          </material>
        </visual>
        <self_collide>0</self_collide>
        <enable_wind>0</enable_wind>
        <kinematic>0</kinematic>
      </link>
    </model>
    <model name='logo_ground'>
      <static>1</static>
      <link name='logo_ground::link'>
        <inertial>
          <mass>0.5</mass>
          <inertia>
            <ixx>0.001</ixx>
            <ixy>0</ixy>
            <ixz>0</ixz>
            <iyy>0.001</iyy>
            <iyz>0</iyz>
            <izz>0.001</izz>
          </inertia>
        </inertial>
        <collision name='collision'>
          <geometry>
            <box>
              <size>10 10 0.01</size>
            </box>
          </geometry>
          <max_contacts>10</max_contacts>
          <surface>
            <bounce/>
            <friction>
              <ode/>
              <torsional>
                <ode/>
              </torsional>
            </friction>
            <contact>
              <ode/>
            </contact>
          </surface>
        </collision>
        <visual name='visual'>
          <cast_shadows>0</cast_shadows>
          <geometry>
            <box>
              <size>10 10 0.01</size>
            </box>
          </geometry>
          <material>
            <script>
              <uri>model://logo_ground/materials/scripts</uri>
              <uri>model://logo_ground/materials/textures</uri>
              <name>Cube/logo_ground</name>
            </script>
          </material>
        </visual>
        <pose frame=''>0 0 0.01 0 -0 0</pose>
        <self_collide>0</self_collide>
        <enable_wind>0</enable_wind>
        <kinematic>0</kinematic>
      </link>
    </model>
    <physics name='default_physics' default='0' type='ode'>
      <ode>
        <solver>
          <type>quick</type>
          <iters>150</iters>
          <sor>1.3</sor>
          <use_dynamic_moi_rescaling>0</use_dynamic_moi_rescaling>
        </solver>
        <constraints>
          <cfm>1e-05</cfm>
          <erp>0.2</erp>
          <contact_max_correcting_vel>1000</contact_max_correcting_vel>
          <contact_surface_layer>0.01</contact_surface_layer>
        </constraints>
      </ode>
      <max_step_size>0.004</max_step_size>
      <real_time_factor>1000</real_time_factor>
      <real_time_update_rate>250</real_time_update_rate>
    </physics>
    <gravity>0 0 -9.8066</gravity>
    <magnetic_field>6e-06 2.3e-05 -4.2e-05</magnetic_field>
    <atmosphere type='adiabatic'/>
    <scene>
      <ambient>0.4 0.4 0.4 1</ambient>
      <background>0.7 0.7 0.7 1</background>
      <shadows>1</shadows>
    </scene>
    <wind/>
    <spherical_coordinates>
      <surface_model>EARTH_WGS84</surface_model>
      <latitude_deg>0</latitude_deg>
      <longitude_deg>0</longitude_deg>
      <elevation>0</elevation>
      <heading_deg>0</heading_deg>
    </spherical_coordinates>
    <model name='typhoon_h480'>
      <link name='base_link'>
        <pose frame=''>0 0 0 0 -0 0</pose>
        <inertial>
          <pose frame=''>0.001005 0 -0.009004 0 -0 0</pose>
          <mass>2.02</mass>
          <inertia>
            <ixx>0.011</ixx>
            <ixy>0</ixy>
            <ixz>0</ixz>
            <iyy>0.015</iyy>
            <iyz>0</iyz>
            <izz>0.021</izz>
          </inertia>
        </inertial>
        <collision name='base_link_collision'>
          <pose frame=''>0 0 0 0 -0 0</pose>
          <geometry>
            <box>
              <size>0.67 0.67 0.15</size>
            </box>
          </geometry>
          <surface>
            <contact>
              <ode>
                <min_depth>0.001</min_depth>
                <max_vel>0</max_vel>
              </ode>
            </contact>
            <friction>
              <ode/>
              <torsional>
                <ode/>
              </torsional>
            </friction>
            <bounce/>
          </surface>
          <max_contacts>10</max_contacts>
        </collision>
        <visual name='base_link_visual'>
          <pose frame=''>0 0 0 0 -0 3.14159</pose>
          <geometry>
            <mesh>
              <scale>0.001 0.001 0.001</scale>
              <uri>model://typhoon_h480/meshes/main_body_remeshed_v3.stl</uri>
            </mesh>
          </geometry>
          <material>
            <script>
              <name>Gazebo/DarkGrey</name>
              <uri>file://media/materials/scripts/gazebo.material</uri>
            </script>
          </material>
        </visual>
        <gravity>1</gravity>
        <velocity_decay/>
        <self_collide>0</self_collide>
        <enable_wind>0</enable_wind>
        <kinematic>0</kinematic>
      </link>
      <link name='cgo3_mount_link'>
        <inertial>
          <pose frame=''>-0.041 0 -0.162 0 -0 0</pose>
          <mass>0.1</mass>
          <inertia>
            <ixx>0.001</ixx>
            <ixy>0</ixy>
            <ixz>0</ixz>
            <iyy>0.001</iyy>
            <iyz>0</iyz>
            <izz>0.001</izz>
          </inertia>
        </inertial>
        <visual name='cgo3_mount_visual'>
          <pose frame=''>0 0 0 0 -0 0</pose>
          <geometry>
            <mesh>
              <scale>0.001 0.001 0.001</scale>
              <uri>model://typhoon_h480/meshes/cgo3_mount_remeshed_v1.stl</uri>
            </mesh>
          </geometry>
          <material>
            <script>
              <name>Gazebo/DarkGrey</name>
              <uri>file://media/materials/scripts/gazebo.material</uri>
            </script>
          </material>
        </visual>
        <self_collide>0</self_collide>
        <enable_wind>0</enable_wind>
        <kinematic>0</kinematic>
      </link>
      <joint name='cgo3_mount_joint' type='revolute'>
        <child>cgo3_mount_link</child>
        <parent>base_link</parent>
        <pose frame=''>0 0 0 0 -0 0</pose>
        <axis>
          <xyz>0 0 1</xyz>
          <limit>
            <lower>0</lower>
            <upper>0</upper>
            <effort>100</effort>
            <velocity>-1</velocity>
          </limit>
          <dynamics>
            <damping>1</damping>
            <spring_reference>0</spring_reference>
            <spring_stiffness>0</spring_stiffness>
          </dynamics>
          <use_parent_model_frame>1</use_parent_model_frame>
        </axis>
        <physics>
          <ode>
            <implicit_spring_damper>1</implicit_spring_damper>
            <limit>
              <cfm>0</cfm>
              <erp>0.2</erp>
            </limit>
          </ode>
        </physics>
      </joint>
      <link name='cgo3_vertical_arm_link'>
        <inertial>
          <pose frame=''>-0.041 0 -0.162 0 -0 0</pose>
          <mass>0.1</mass>
          <inertia>
            <ixx>0.001</ixx>
            <ixy>0</ixy>
            <ixz>0</ixz>
            <iyy>0.001</iyy>
            <iyz>0</iyz>
            <izz>0.001</izz>
          </inertia>
        </inertial>
        <visual name='cgo3_vertical_arm_visual'>
          <pose frame=''>-0.051 0 0 0 -0 3.14159</pose>
          <geometry>
            <mesh>
              <scale>0.001 0.001 0.001</scale>
              <uri>model://typhoon_h480/meshes/cgo3_vertical_arm_remeshed_v1.stl</uri>
            </mesh>
          </geometry>
          <material>
            <script>
              <name>Gazebo/DarkGrey</name>
              <uri>file://media/materials/scripts/gazebo.material</uri>
            </script>
          </material>
        </visual>
        <self_collide>0</self_collide>
        <enable_wind>0</enable_wind>
        <kinematic>0</kinematic>
      </link>
      <joint name='cgo3_vertical_arm_joint' type='revolute'>
        <child>cgo3_vertical_arm_link</child>
        <parent>cgo3_mount_link</parent>
        <pose frame=''>-0.026 0 -0.1 0 -0 0</pose>
        <axis>
          <xyz>0 0 1</xyz>
          <limit>
            <lower>-1e+16</lower>
            <upper>1e+16</upper>
            <effort>100</effort>
            <velocity>-1</velocity>
          </limit>
          <dynamics>
            <damping>0.1</damping>
            <spring_reference>0</spring_reference>
            <spring_stiffness>0</spring_stiffness>
          </dynamics>
          <use_parent_model_frame>1</use_parent_model_frame>
        </axis>
        <physics>
          <ode>
            <implicit_spring_damper>1</implicit_spring_damper>
            <limit>
              <cfm>0.1</cfm>
              <erp>0.2</erp>
            </limit>
          </ode>
        </physics>
      </joint>
      <link name='cgo3_horizontal_arm_link'>
        <inertial>
          <pose frame=''>-0.041 0 -0.081 0 -0 0</pose>
          <mass>0.1</mass>
          <inertia>
            <ixx>0.001</ixx>
            <ixy>0</ixy>
            <ixz>0</ixz>
            <iyy>0.001</iyy>
            <iyz>0</iyz>
            <izz>0.001</izz>
          </inertia>
        </inertial>
        <visual name='cgo3_horizontal_arm_visual'>
          <pose frame=''>-0.05 0 0 0 -0 3.14159</pose>
          <geometry>
            <mesh>
              <scale>0.001 0.001 0.001</scale>
              <uri>model://typhoon_h480/meshes/cgo3_horizontal_arm_remeshed_v1.stl</uri>
            </mesh>
          </geometry>
          <material>
            <script>
              <name>Gazebo/DarkGrey</name>
              <uri>file://media/materials/scripts/gazebo.material</uri>
            </script>
          </material>
        </visual>
        <self_collide>0</self_collide>
        <enable_wind>0</enable_wind>
        <kinematic>0</kinematic>
      </link>
      <joint name='cgo3_horizontal_arm_joint' type='revolute'>
        <child>cgo3_horizontal_arm_link</child>
        <parent>cgo3_vertical_arm_link</parent>
        <pose frame=''>-0.07 0 -0.162 0 -0 0</pose>
        <axis>
          <xyz>-1 0 0</xyz>
          <limit>
            <lower>-0.785398</lower>
            <upper>0.785398</upper>
            <effort>100</effort>
            <velocity>-1</velocity>
          </limit>
          <dynamics>
            <damping>0.1</damping>
            <spring_reference>0</spring_reference>
            <spring_stiffness>0</spring_stiffness>
          </dynamics>
          <use_parent_model_frame>1</use_parent_model_frame>
        </axis>
        <physics>
          <ode>
            <implicit_spring_damper>1</implicit_spring_damper>
            <limit>
              <cfm>0.1</cfm>
              <erp>0.2</erp>
            </limit>
          </ode>
        </physics>
      </joint>
      <link name='cgo3_camera_link'>
        <inertial>
          <pose frame=''>-0.041 0 -0.162 0 -0 0</pose>
          <mass>0.1</mass>
          <inertia>
            <ixx>0.001</ixx>
            <ixy>0</ixy>
            <ixz>0</ixz>
            <iyy>0.001</iyy>
            <iyz>0</iyz>
            <izz>0.001</izz>
          </inertia>
        </inertial>
        <collision name='cgo3_camera_collision'>
          <pose frame=''>-0.041 0 -0.162 0 -0 0</pose>
          <geometry>
            <sphere>
              <radius>0.035</radius>
            </sphere>
          </geometry>
          <surface>
            <friction>
              <ode>
                <mu>1</mu>
                <mu2>1</mu2>
              </ode>
              <torsional>
                <ode/>
              </torsional>
            </friction>
            <contact>
              <ode>
                <kp>1e+08</kp>
                <kd>1</kd>
                <max_vel>0.01</max_vel>
                <min_depth>0.001</min_depth>
              </ode>
            </contact>
            <bounce/>
          </surface>
          <max_contacts>10</max_contacts>
        </collision>
        <visual name='cgo3_camera_visual'>
          <pose frame=''>-0.05 0 0 0 -0 3.14159</pose>
          <geometry>
            <mesh>
              <scale>0.001 0.001 0.001</scale>
              <uri>model://typhoon_h480/meshes/cgo3_camera_remeshed_v1.stl</uri>
            </mesh>
          </geometry>
          <material>
            <script>
              <name>Gazebo/DarkGrey</name>
              <uri>file://media/materials/scripts/gazebo.material</uri>
            </script>
          </material>
        </visual>
        <sensor name='camera_imu' type='imu'>
          <always_on>1</always_on>
          <imu/>
        </sensor>
        <sensor name='camera' type='camera'>
          <camera name='__default__'>
            <horizontal_fov>2.0944</horizontal_fov>
            <image>
              <width>1280</width>
              <height>720</height>
            </image>
            <clip>
              <near>0.1</near>
              <far>100</far>
            </clip>
            <noise>
              <type>gaussian</type>
              <mean>0</mean>
              <stddev>0.001</stddev>
            </noise>
            <lens>
              <type>custom</type>
              <custom_function>
                <c1>1.05</c1>
                <c2>4</c2>
                <f>1</f>
                <fun>tan</fun>
              </custom_function>
              <scale_to_hfov>1</scale_to_hfov>
              <cutoff_angle>3.1415</cutoff_angle>
            </lens>
          </camera>
          <always_on>1</always_on>
          <update_rate>30</update_rate>
          <visualize>1</visualize>
          <plugin name='camera_plugin' filename='libgazebo_ros_camera.so'>
            <robotNamespace>/prometheus/sensor</robotNamespace>
            <alwaysOn>1</alwaysOn>
            <imageTopicName>image_raw</imageTopicName>
            <cameraInfoTopicName>camera_info</cameraInfoTopicName>
            <updateRate>30.0</updateRate>
            <cameraName>gimbal_camera</cameraName>
            <frameName>/gimbal_camera</frameName>
            <CxPrime>640</CxPrime>
            <Cx>640</Cx>
            <Cy>360</Cy>
            <hackBaseline>0</hackBaseline>
            <focalLength>369.502083</focalLength>
            <distortionK1>0.0</distortionK1>
            <distortionK2>0.0</distortionK2>
            <distortionK3>0.0</distortionK3>
            <distortionT1>0.0</distortionT1>
            <distortionT2>0.0</distortionT2>
          </plugin>
        </sensor>
        <self_collide>0</self_collide>
        <enable_wind>0</enable_wind>
        <kinematic>0</kinematic>
      </link>
      <joint name='cgo3_camera_joint' type='revolute'>
        <child>cgo3_camera_link</child>
        <parent>cgo3_horizontal_arm_link</parent>
        <pose frame=''>-0.01 0.03 -0.162 0 -0 0</pose>
        <axis>
          <xyz>0 -1 0</xyz>
          <limit>
            <lower>-1.05</lower>
            <upper>2.09</upper>
            <effort>100</effort>
            <velocity>-1</velocity>
          </limit>
          <dynamics>
            <damping>0.1</damping>
            <spring_reference>0</spring_reference>
            <spring_stiffness>0</spring_stiffness>
          </dynamics>
          <use_parent_model_frame>1</use_parent_model_frame>
        </axis>
        <physics>
          <ode>
            <implicit_spring_damper>1</implicit_spring_damper>
            <limit>
              <cfm>0.1</cfm>
              <erp>0.2</erp>
            </limit>
          </ode>
        </physics>
      </joint>
      <link name='left_leg'>
        <inertial>
          <pose frame=''>0 -0.14314 -0.207252 0 -0 0</pose>
          <mass>0.1</mass>
          <inertia>
            <ixx>0.001</ixx>
            <ixy>0</ixy>
            <ixz>0</ixz>
            <iyy>0.001</iyy>
            <iyz>0</iyz>
            <izz>0.001</izz>
          </inertia>
        </inertial>
        <collision name='collision'>
          <pose frame=''>-0.005 -0.14314 -0.207252 0 1.56893 0</pose>
          <geometry>
            <cylinder>
              <radius>0.012209</radius>
              <length>0.3</length>
            </cylinder>
          </geometry>
          <surface>
            <friction>
              <ode>
                <mu>1</mu>
                <mu2>1</mu2>
              </ode>
              <torsional>
                <ode/>
              </torsional>
            </friction>
            <contact>
              <ode>
                <kp>1e+08</kp>
                <kd>1</kd>
                <max_vel>0.01</max_vel>
                <min_depth>0.001</min_depth>
              </ode>
            </contact>
            <bounce/>
          </surface>
          <max_contacts>10</max_contacts>
        </collision>
        <collision name='collision_bar'>
          <pose frame=''>0.00052 -0.08503 -0.121187 -0.501318 0 0</pose>
          <geometry>
            <cylinder>
              <radius>0.00914984</radius>
              <length>0.176893</length>
            </cylinder>
          </geometry>
          <surface>
            <friction>
              <ode>
                <mu>1</mu>
                <mu2>1</mu2>
              </ode>
              <torsional>
                <ode/>
              </torsional>
            </friction>
            <contact>
              <ode>
                <kp>1e+08</kp>
                <kd>1</kd>
                <max_vel>0.01</max_vel>
                <min_depth>0.001</min_depth>
              </ode>
            </contact>
            <bounce/>
          </surface>
          <max_contacts>10</max_contacts>
        </collision>
        <visual name='base_link_left_leg'>
          <pose frame=''>0 0 0 0 -0 0</pose>
          <geometry>
            <mesh>
              <scale>0.001 0.001 0.001</scale>
              <uri>model://typhoon_h480/meshes/leg2_remeshed_v3.stl</uri>
            </mesh>
          </geometry>
          <material>
            <script>
              <name>Gazebo/DarkGrey</name>
              <uri>file://media/materials/scripts/gazebo.material</uri>
            </script>
          </material>
        </visual>
        <self_collide>0</self_collide>
        <enable_wind>0</enable_wind>
        <kinematic>0</kinematic>
      </link>
      <joint name='left_leg_joint' type='revolute'>
        <child>left_leg</child>
        <parent>base_link</parent>
        <pose frame=''>0.00026 -0.040515 -0.048 0 -0 0</pose>
        <axis>
          <xyz>-1 0 0</xyz>
          <limit>
            <lower>0</lower>
            <upper>1</upper>
            <effort>100</effort>
            <velocity>-1</velocity>
            <stiffness>1e+08</stiffness>
            <dissipation>1</dissipation>
          </limit>
          <dynamics>
            <damping>0.1</damping>
            <spring_reference>0</spring_reference>
            <spring_stiffness>0</spring_stiffness>
          </dynamics>
          <use_parent_model_frame>1</use_parent_model_frame>
        </axis>
        <physics>
          <ode>
            <implicit_spring_damper>1</implicit_spring_damper>
            <limit>
              <cfm>0</cfm>
              <erp>0.2</erp>
            </limit>
          </ode>
        </physics>
      </joint>
      <link name='right_leg'>
        <pose frame=''>0 0 0 0 -0 0</pose>
        <inertial>
          <pose frame=''>0 0.14314 -0.207252 0 -0 0</pose>
          <mass>0.1</mass>
          <inertia>
            <ixx>0.001</ixx>
            <ixy>0</ixy>
            <ixz>0</ixz>
            <iyy>0.001</iyy>
            <iyz>0</iyz>
            <izz>0.001</izz>
          </inertia>
        </inertial>
        <collision name='collision'>
          <pose frame=''>-0.005 0.14314 -0.207252 0 1.56893 0</pose>
          <geometry>
            <cylinder>
              <radius>0.012209</radius>
              <length>0.3</length>
            </cylinder>
          </geometry>
          <surface>
            <friction>
              <ode>
                <mu>1</mu>
                <mu2>1</mu2>
              </ode>
              <torsional>
                <ode/>
              </torsional>
            </friction>
            <contact>
              <ode>
                <kp>1e+08</kp>
                <kd>1</kd>
                <max_vel>0.01</max_vel>
                <min_depth>0.001</min_depth>
              </ode>
            </contact>
            <bounce/>
          </surface>
          <max_contacts>10</max_contacts>
        </collision>
        <collision name='collision_bar'>
          <pose frame=''>0.00052 0.08503 -0.121187 0.501318 -0 0</pose>
          <geometry>
            <cylinder>
              <radius>0.00914984</radius>
              <length>0.176893</length>
            </cylinder>
          </geometry>
          <surface>
            <friction>
              <ode>
                <mu>1</mu>
                <mu2>1</mu2>
              </ode>
              <torsional>
                <ode/>
              </torsional>
            </friction>
            <contact>
              <ode>
                <kp>1e+08</kp>
                <kd>1</kd>
                <max_vel>0.01</max_vel>
                <min_depth>0.001</min_depth>
              </ode>
            </contact>
            <bounce/>
          </surface>
          <max_contacts>10</max_contacts>
        </collision>
        <visual name='base_link_right_leg'>
          <pose frame=''>0 0 0 0 -0 0</pose>
          <geometry>
            <mesh>
              <scale>0.001 0.001 0.001</scale>
              <uri>model://typhoon_h480/meshes/leg1_remeshed_v3.stl</uri>
            </mesh>
          </geometry>
          <material>
            <script>
              <name>Gazebo/DarkGrey</name>
              <uri>file://media/materials/scripts/gazebo.material</uri>
            </script>
          </material>
        </visual>
        <self_collide>0</self_collide>
        <enable_wind>0</enable_wind>
        <kinematic>0</kinematic>
      </link>
      <joint name='right_leg_joint' type='revolute'>
        <child>right_leg</child>
        <parent>base_link</parent>
        <pose frame=''>0.00026 0.040515 -0.048 0 -0 0</pose>
        <axis>
          <xyz>1 0 0</xyz>
          <limit>
            <lower>0</lower>
            <upper>1</upper>
            <effort>100</effort>
            <velocity>-1</velocity>
            <stiffness>1e+08</stiffness>
            <dissipation>1</dissipation>
          </limit>
          <dynamics>
            <damping>0.1</damping>
            <spring_reference>0</spring_reference>
            <spring_stiffness>0</spring_stiffness>
          </dynamics>
          <use_parent_model_frame>1</use_parent_model_frame>
        </axis>
        <physics>
          <ode>
            <implicit_spring_damper>1</implicit_spring_damper>
            <limit>
              <cfm>0</cfm>
              <erp>0.2</erp>
            </limit>
          </ode>
        </physics>
      </joint>
      <link name='typhoon_h480/imu_link'>
        <pose frame=''>0 0 0 0 -0 0</pose>
        <inertial>
          <pose frame=''>0 0 0 0 -0 0</pose>
          <mass>0.015</mass>
          <inertia>
            <ixx>1e-05</ixx>
            <ixy>0</ixy>
            <ixz>0</ixz>
            <iyy>1e-05</iyy>
            <iyz>0</iyz>
            <izz>1e-05</izz>
          </inertia>
        </inertial>
        <self_collide>0</self_collide>
        <enable_wind>0</enable_wind>
        <kinematic>0</kinematic>
      </link>
      <joint name='typhoon_h480/imu_joint' type='revolute'>
        <child>typhoon_h480/imu_link</child>
        <parent>base_link</parent>
        <axis>
          <xyz>1 0 0</xyz>
          <limit>
            <lower>0</lower>
            <upper>0</upper>
            <effort>0</effort>
            <velocity>0</velocity>
          </limit>
          <dynamics>
            <spring_reference>0</spring_reference>
            <spring_stiffness>0</spring_stiffness>
          </dynamics>
          <use_parent_model_frame>1</use_parent_model_frame>
        </axis>
      </joint>
      <link name='rotor_3'>
        <pose frame=''>0.211396 0.119762 0.082219 0 -0 0</pose>
        <inertial>
          <pose frame=''>0 0 0 0 -0 0</pose>
          <mass>0.005</mass>
          <inertia>
            <ixx>9.75e-07</ixx>
            <ixy>0</ixy>
            <ixz>0</ixz>
            <iyy>0.000273104</iyy>
            <iyz>0</iyz>
            <izz>0.000274004</izz>
          </inertia>
        </inertial>
        <collision name='rotor_3_collision'>
          <pose frame=''>0 0 0 0 -0 0</pose>
          <geometry>
            <cylinder>
              <length>0.005</length>
              <radius>0.128</radius>
            </cylinder>
          </geometry>
          <surface>
            <contact>
              <ode/>
            </contact>
            <friction>
              <ode/>
              <torsional>
                <ode/>
              </torsional>
            </friction>
            <bounce/>
          </surface>
          <max_contacts>10</max_contacts>
        </collision>
        <visual name='rotor_3_visual'>
          <pose frame=''>-0.211396 -0.119762 -0.082219 0 -0 0</pose>
          <geometry>
            <mesh>
              <scale>0.001 0.001 0.001</scale>
              <uri>model://typhoon_h480/meshes/prop_ccw_assembly_remeshed_v3.stl</uri>
            </mesh>
          </geometry>
          <material>
            <script>
              <name>Gazebo/Blue</name>
              <uri>file://media/materials/scripts/gazebo.material</uri>
            </script>
          </material>
        </visual>
        <gravity>1</gravity>
        <velocity_decay/>
        <self_collide>0</self_collide>
        <enable_wind>0</enable_wind>
        <kinematic>0</kinematic>
      </link>
      <joint name='rotor_3_joint' type='revolute'>
        <child>rotor_3</child>
        <parent>base_link</parent>
        <axis>
          <xyz>0 0 1</xyz>
          <limit>
            <lower>-1e+16</lower>
            <upper>1e+16</upper>
            <effort>10</effort>
            <velocity>-1</velocity>
          </limit>
          <dynamics>
            <damping>0.005</damping>
            <spring_reference>0</spring_reference>
            <spring_stiffness>0</spring_stiffness>
          </dynamics>
          <use_parent_model_frame>1</use_parent_model_frame>
        </axis>
        <physics>
          <ode>
            <implicit_spring_damper>1</implicit_spring_damper>
            <limit>
              <cfm>0</cfm>
              <erp>0.2</erp>
            </limit>
          </ode>
        </physics>
      </joint>
      <link name='rotor_0'>
        <pose frame=''>-0.209396 0.122762 0.082219 0 -0 2.0944</pose>
        <inertial>
          <pose frame=''>0 0 0 0 -0 0</pose>
          <mass>0.005</mass>
          <inertia>
            <ixx>9.75e-07</ixx>
            <ixy>0</ixy>
            <ixz>0</ixz>
            <iyy>0.000273104</iyy>
            <iyz>0</iyz>
            <izz>0.000274004</izz>
          </inertia>
        </inertial>
        <collision name='rotor_0_collision'>
          <pose frame=''>0 0 0 0 -0 0</pose>
          <geometry>
            <cylinder>
              <length>0.005</length>
              <radius>0.128</radius>
            </cylinder>
          </geometry>
          <surface>
            <contact>
              <ode/>
            </contact>
            <friction>
              <ode/>
              <torsional>
                <ode/>
              </torsional>
            </friction>
            <bounce/>
          </surface>
          <max_contacts>10</max_contacts>
        </collision>
        <visual name='rotor_0_visual'>
          <pose frame=''>-0.211396 -0.119762 -0.082219 0 -0 0</pose>
          <geometry>
            <mesh>
              <scale>0.001 0.001 0.001</scale>
              <uri>model://typhoon_h480/meshes/prop_ccw_assembly_remeshed_v3.stl</uri>
            </mesh>
          </geometry>
          <material>
            <script>
              <name>Gazebo/Blue</name>
              <uri>file://media/materials/scripts/gazebo.material</uri>
            </script>
          </material>
        </visual>
        <gravity>1</gravity>
        <velocity_decay/>
        <self_collide>0</self_collide>
        <enable_wind>0</enable_wind>
        <kinematic>0</kinematic>
      </link>
      <joint name='rotor_0_joint' type='revolute'>
        <child>rotor_0</child>
        <parent>base_link</parent>
        <axis>
          <xyz>0 0 1</xyz>
          <limit>
            <lower>-1e+16</lower>
            <upper>1e+16</upper>
            <effort>10</effort>
            <velocity>-1</velocity>
          </limit>
          <dynamics>
            <damping>0.005</damping>
            <spring_reference>0</spring_reference>
            <spring_stiffness>0</spring_stiffness>
          </dynamics>
          <use_parent_model_frame>1</use_parent_model_frame>
        </axis>
        <physics>
          <ode>
            <implicit_spring_damper>1</implicit_spring_damper>
            <limit>
              <cfm>0</cfm>
              <erp>0.2</erp>
            </limit>
          </ode>
        </physics>
      </joint>
      <link name='rotor_4'>
        <pose frame=''>-0.001879 0.242705 0.082217 0 -0 0</pose>
        <inertial>
          <pose frame=''>0 0 0 0 -0 0</pose>
          <mass>0.005</mass>
          <inertia>
            <ixx>9.75e-07</ixx>
            <ixy>0</ixy>
            <ixz>0</ixz>
            <iyy>0.000273104</iyy>
            <iyz>0</iyz>
            <izz>0.000274004</izz>
          </inertia>
        </inertial>
        <collision name='rotor_4_collision'>
          <pose frame=''>0 0 0 0 -0 0</pose>
          <geometry>
            <cylinder>
              <length>0.005</length>
              <radius>0.128</radius>
            </cylinder>
          </geometry>
          <surface>
            <contact>
              <ode/>
            </contact>
            <friction>
              <ode/>
              <torsional>
                <ode/>
              </torsional>
            </friction>
            <bounce/>
          </surface>
          <max_contacts>10</max_contacts>
        </collision>
        <visual name='rotor_4_visual'>
          <pose frame=''>0.001879 -0.242705 -0.082217 0 -0 0</pose>
          <geometry>
            <mesh>
              <scale>0.001 0.001 0.001</scale>
              <uri>model://typhoon_h480/meshes/prop_cw_assembly_remeshed_v3.stl</uri>
            </mesh>
          </geometry>
          <material>
            <script>
              <name>Gazebo/DarkGrey</name>
              <uri>file://media/materials/scripts/gazebo.material</uri>
            </script>
          </material>
        </visual>
        <gravity>1</gravity>
        <velocity_decay/>
        <self_collide>0</self_collide>
        <enable_wind>0</enable_wind>
        <kinematic>0</kinematic>
      </link>
      <joint name='rotor_4_joint' type='revolute'>
        <child>rotor_4</child>
        <parent>base_link</parent>
        <axis>
          <xyz>0 0 1</xyz>
          <limit>
            <lower>-1e+16</lower>
            <upper>1e+16</upper>
            <effort>10</effort>
            <velocity>-1</velocity>
          </limit>
          <dynamics>
            <damping>0.005</damping>
            <spring_reference>0</spring_reference>
            <spring_stiffness>0</spring_stiffness>
          </dynamics>
          <use_parent_model_frame>1</use_parent_model_frame>
        </axis>
        <physics>
          <ode>
            <implicit_spring_damper>1</implicit_spring_damper>
            <limit>
              <cfm>0</cfm>
              <erp>0.2</erp>
            </limit>
          </ode>
        </physics>
      </joint>
      <link name='rotor_1'>
        <pose frame=''>0.211396 -0.119762 0.082219 0 0 -2.0944</pose>
        <inertial>
          <pose frame=''>0 0 0 0 -0 0</pose>
          <mass>0.005</mass>
          <inertia>
            <ixx>9.75e-07</ixx>
            <ixy>0</ixy>
            <ixz>0</ixz>
            <iyy>0.000273104</iyy>
            <iyz>0</iyz>
            <izz>0.000274004</izz>
          </inertia>
        </inertial>
        <collision name='rotor_1_collision'>
          <pose frame=''>0 0 0 0 -0 0</pose>
          <geometry>
            <cylinder>
              <length>0.005</length>
              <radius>0.128</radius>
            </cylinder>
          </geometry>
          <surface>
            <contact>
              <ode/>
            </contact>
            <friction>
              <ode/>
              <torsional>
                <ode/>
              </torsional>
            </friction>
            <bounce/>
          </surface>
          <max_contacts>10</max_contacts>
        </collision>
        <visual name='rotor_1_visual'>
          <pose frame=''>0.001879 -0.242705 -0.082217 0 -0 0</pose>
          <geometry>
            <mesh>
              <scale>0.001 0.001 0.001</scale>
              <uri>model://typhoon_h480/meshes/prop_cw_assembly_remeshed_v3.stl</uri>
            </mesh>
          </geometry>
          <material>
            <script>
              <name>Gazebo/DarkGrey</name>
              <uri>file://media/materials/scripts/gazebo.material</uri>
            </script>
          </material>
        </visual>
        <gravity>1</gravity>
        <velocity_decay/>
        <self_collide>0</self_collide>
        <enable_wind>0</enable_wind>
        <kinematic>0</kinematic>
      </link>
      <joint name='rotor_1_joint' type='revolute'>
        <child>rotor_1</child>
        <parent>base_link</parent>
        <axis>
          <xyz>0 0 1</xyz>
          <limit>
            <lower>-1e+16</lower>
            <upper>1e+16</upper>
            <effort>10</effort>
            <velocity>-1</velocity>
          </limit>
          <dynamics>
            <damping>0.005</damping>
            <spring_reference>0</spring_reference>
            <spring_stiffness>0</spring_stiffness>
          </dynamics>
          <use_parent_model_frame>1</use_parent_model_frame>
        </axis>
        <physics>
          <ode>
            <implicit_spring_damper>1</implicit_spring_damper>
            <limit>
              <cfm>0</cfm>
              <erp>0.2</erp>
            </limit>
          </ode>
        </physics>
      </joint>
      <link name='rotor_5'>
        <pose frame=''>-0.001879 -0.242705 0.082217 0 0 -2.0944</pose>
        <inertial>
          <pose frame=''>0 0 0 0 -0 0</pose>
          <mass>0.005</mass>
          <inertia>
            <ixx>9.75e-07</ixx>
            <ixy>0</ixy>
            <ixz>0</ixz>
            <iyy>0.000273104</iyy>
            <iyz>0</iyz>
            <izz>0.000274004</izz>
          </inertia>
        </inertial>
        <collision name='rotor_5_collision'>
          <pose frame=''>0 0 0 0 -0 0</pose>
          <geometry>
            <cylinder>
              <length>0.005</length>
              <radius>0.128</radius>
            </cylinder>
          </geometry>
          <surface>
            <contact>
              <ode/>
            </contact>
            <friction>
              <ode/>
              <torsional>
                <ode/>
              </torsional>
            </friction>
            <bounce/>
          </surface>
          <max_contacts>10</max_contacts>
        </collision>
        <visual name='rotor_5_visual'>
          <pose frame=''>-0.211396 -0.119762 -0.082219 0 -0 0</pose>
          <geometry>
            <mesh>
              <scale>0.001 0.001 0.001</scale>
              <uri>model://typhoon_h480/meshes/prop_ccw_assembly_remeshed_v3.stl</uri>
            </mesh>
          </geometry>
          <material>
            <script>
              <name>Gazebo/Blue</name>
              <uri>file://media/materials/scripts/gazebo.material</uri>
            </script>
          </material>
        </visual>
        <gravity>1</gravity>
        <velocity_decay/>
        <self_collide>0</self_collide>
        <enable_wind>0</enable_wind>
        <kinematic>0</kinematic>
      </link>
      <joint name='rotor_5_joint' type='revolute'>
        <child>rotor_5</child>
        <parent>base_link</parent>
        <axis>
          <xyz>0 0 1</xyz>
          <limit>
            <lower>-1e+16</lower>
            <upper>1e+16</upper>
            <effort>10</effort>
            <velocity>-1</velocity>
          </limit>
          <dynamics>
            <damping>0.005</damping>
            <spring_reference>0</spring_reference>
            <spring_stiffness>0</spring_stiffness>
          </dynamics>
          <use_parent_model_frame>1</use_parent_model_frame>
        </axis>
        <physics>
          <ode>
            <implicit_spring_damper>1</implicit_spring_damper>
            <limit>
              <cfm>0</cfm>
              <erp>0.2</erp>
            </limit>
          </ode>
        </physics>
      </joint>
      <link name='rotor_2'>
        <pose frame=''>-0.209396 -0.122762 0.082219 0 -0 2.0944</pose>
        <inertial>
          <pose frame=''>0 0 0 0 -0 0</pose>
          <mass>0.005</mass>
          <inertia>
            <ixx>9.75e-07</ixx>
            <ixy>0</ixy>
            <ixz>0</ixz>
            <iyy>0.000273104</iyy>
            <iyz>0</iyz>
            <izz>0.000274004</izz>
          </inertia>
        </inertial>
        <collision name='rotor_2_collision'>
          <pose frame=''>0 0 0 0 -0 0</pose>
          <geometry>
            <cylinder>
              <length>0.005</length>
              <radius>0.128</radius>
            </cylinder>
          </geometry>
          <surface>
            <contact>
              <ode/>
            </contact>
            <friction>
              <ode/>
              <torsional>
                <ode/>
              </torsional>
            </friction>
            <bounce/>
          </surface>
          <max_contacts>10</max_contacts>
        </collision>
        <visual name='rotor_2_visual'>
          <pose frame=''>0.001879 -0.242705 -0.082217 0 -0 0</pose>
          <geometry>
            <mesh>
              <scale>0.001 0.001 0.001</scale>
              <uri>model://typhoon_h480/meshes/prop_cw_assembly_remeshed_v3.stl</uri>
            </mesh>
          </geometry>
          <material>
            <script>
              <name>Gazebo/DarkGrey</name>
              <uri>file://media/materials/scripts/gazebo.material</uri>
            </script>
          </material>
        </visual>
        <gravity>1</gravity>
        <velocity_decay/>
        <self_collide>0</self_collide>
        <enable_wind>0</enable_wind>
        <kinematic>0</kinematic>
      </link>
      <joint name='rotor_2_joint' type='revolute'>
        <child>rotor_2</child>
        <parent>base_link</parent>
        <axis>
          <xyz>0 0 1</xyz>
          <limit>
            <lower>-1e+16</lower>
            <upper>1e+16</upper>
            <effort>10</effort>
            <velocity>-1</velocity>
          </limit>
          <dynamics>
            <damping>0.005</damping>
            <spring_reference>0</spring_reference>
            <spring_stiffness>0</spring_stiffness>
          </dynamics>
          <use_parent_model_frame>1</use_parent_model_frame>
        </axis>
        <physics>
          <ode>
            <implicit_spring_damper>1</implicit_spring_damper>
            <limit>
              <cfm>0</cfm>
              <erp>0.2</erp>
            </limit>
          </ode>
        </physics>
      </joint>
      <link name='gps::link'>
        <pose frame=''>0 0 0 0 -0 0</pose>
        <inertial>
          <pose frame=''>0 0 0 0 -0 0</pose>
          <mass>0.015</mass>
          <inertia>
            <ixx>1e-05</ixx>
            <ixy>0</ixy>
            <ixz>0</ixz>
            <iyy>1e-05</iyy>
            <iyz>0</iyz>
            <izz>1e-05</izz>
          </inertia>
        </inertial>
        <visual name='visual'>
          <geometry>
            <cylinder>
              <radius>0.01</radius>
              <length>0.002</length>
            </cylinder>
          </geometry>
          <material>
            <script>
              <name>Gazebo/Black</name>
              <uri>__default__</uri>
            </script>
          </material>
        </visual>
        <sensor name='gps' type='gps'>
          <pose frame=''>0 0 0 0 -0 0</pose>
          <update_rate>5</update_rate>
          <always_on>1</always_on>
          <visualize>0</visualize>
          <plugin name='gps_plugin' filename='libgazebo_gps_plugin.so'>
            <robotNamespace/>
            <gpsNoise>1</gpsNoise>
            <gpsXYRandomWalk>2.0</gpsXYRandomWalk>
            <gpsZRandomWalk>4.0</gpsZRandomWalk>
            <gpsXYNoiseDensity>2.0e-4</gpsXYNoiseDensity>
            <gpsZNoiseDensity>4.0e-4</gpsZNoiseDensity>
            <gpsVXYNoiseDensity>0.2</gpsVXYNoiseDensity>
            <gpsVZNoiseDensity>0.4</gpsVZNoiseDensity>
          </plugin>
          <gps/>
        </sensor>
        <self_collide>0</self_collide>
        <enable_wind>0</enable_wind>
        <kinematic>0</kinematic>
      </link>
      <joint name='gps_joint' type='fixed'>
        <child>gps::link</child>
        <parent>base_link</parent>
      </joint>
      <plugin name='rosbag' filename='libgazebo_multirotor_base_plugin.so'>
        <robotNamespace/>
        <linkName>base_link</linkName>
        <rotorVelocitySlowdownSim>10</rotorVelocitySlowdownSim>
      </plugin>
      <plugin name='front_right_motor_model' filename='libgazebo_motor_model.so'>
        <robotNamespace/>
        <jointName>rotor_0_joint</jointName>
        <linkName>rotor_0</linkName>
        <turningDirection>cw</turningDirection>
        <timeConstantUp>0.0125</timeConstantUp>
        <timeConstantDown>0.025</timeConstantDown>
        <maxRotVelocity>1500</maxRotVelocity>
        <motorConstant>8.54858e-06</motorConstant>
        <momentConstant>0.06</momentConstant>
        <commandSubTopic>/gazebo/command/motor_speed</commandSubTopic>
        <motorNumber>5</motorNumber>
        <rotorDragCoefficient>0.000806428</rotorDragCoefficient>
        <rollingMomentCoefficient>1e-06</rollingMomentCoefficient>
        <motorSpeedPubTopic>/motor_speed/5</motorSpeedPubTopic>
        <rotorVelocitySlowdownSim>10</rotorVelocitySlowdownSim>
      </plugin>
      <plugin name='back_left_motor_model' filename='libgazebo_motor_model.so'>
        <robotNamespace/>
        <jointName>rotor_1_joint</jointName>
        <linkName>rotor_1</linkName>
        <turningDirection>ccw</turningDirection>
        <timeConstantUp>0.0125</timeConstantUp>
        <timeConstantDown>0.025</timeConstantDown>
        <maxRotVelocity>1500</maxRotVelocity>
        <motorConstant>8.54858e-06</motorConstant>
        <momentConstant>0.06</momentConstant>
        <commandSubTopic>/gazebo/command/motor_speed</commandSubTopic>
        <motorNumber>4</motorNumber>
        <rotorDragCoefficient>0.000806428</rotorDragCoefficient>
        <rollingMomentCoefficient>1e-06</rollingMomentCoefficient>
        <motorSpeedPubTopic>/motor_speed/4</motorSpeedPubTopic>
        <rotorVelocitySlowdownSim>10</rotorVelocitySlowdownSim>
      </plugin>
      <plugin name='front_left_motor_model' filename='libgazebo_motor_model.so'>
        <robotNamespace/>
        <jointName>rotor_2_joint</jointName>
        <linkName>rotor_2</linkName>
        <turningDirection>ccw</turningDirection>
        <timeConstantUp>0.0125</timeConstantUp>
        <timeConstantDown>0.025</timeConstantDown>
        <maxRotVelocity>1500</maxRotVelocity>
        <motorConstant>8.54858e-06</motorConstant>
        <momentConstant>0.06</momentConstant>
        <commandSubTopic>/gazebo/command/motor_speed</commandSubTopic>
        <motorNumber>3</motorNumber>
        <rotorDragCoefficient>0.000806428</rotorDragCoefficient>
        <rollingMomentCoefficient>1e-06</rollingMomentCoefficient>
        <motorSpeedPubTopic>/motor_speed/3</motorSpeedPubTopic>
        <rotorVelocitySlowdownSim>10</rotorVelocitySlowdownSim>
      </plugin>
      <plugin name='back_right_motor_model' filename='libgazebo_motor_model.so'>
        <robotNamespace/>
        <jointName>rotor_3_joint</jointName>
        <linkName>rotor_3</linkName>
        <turningDirection>cw</turningDirection>
        <timeConstantUp>0.0125</timeConstantUp>
        <timeConstantDown>0.025</timeConstantDown>
        <maxRotVelocity>1500</maxRotVelocity>
        <motorConstant>8.54858e-06</motorConstant>
        <momentConstant>0.06</momentConstant>
        <commandSubTopic>/gazebo/command/motor_speed</commandSubTopic>
        <motorNumber>2</motorNumber>
        <rotorDragCoefficient>0.000806428</rotorDragCoefficient>
        <rollingMomentCoefficient>1e-06</rollingMomentCoefficient>
        <motorSpeedPubTopic>/motor_speed/2</motorSpeedPubTopic>
        <rotorVelocitySlowdownSim>10</rotorVelocitySlowdownSim>
      </plugin>
      <plugin name='back_left_motor_model' filename='libgazebo_motor_model.so'>
        <robotNamespace/>
        <jointName>rotor_4_joint</jointName>
        <linkName>rotor_4</linkName>
        <turningDirection>ccw</turningDirection>
        <timeConstantUp>0.0125</timeConstantUp>
        <timeConstantDown>0.025</timeConstantDown>
        <maxRotVelocity>1500</maxRotVelocity>
        <motorConstant>8.54858e-06</motorConstant>
        <momentConstant>0.06</momentConstant>
        <commandSubTopic>/gazebo/command/motor_speed</commandSubTopic>
        <motorNumber>1</motorNumber>
        <rotorDragCoefficient>0.000806428</rotorDragCoefficient>
        <rollingMomentCoefficient>1e-06</rollingMomentCoefficient>
        <motorSpeedPubTopic>/motor_speed/1</motorSpeedPubTopic>
        <rotorVelocitySlowdownSim>10</rotorVelocitySlowdownSim>
      </plugin>
      <plugin name='front_left_motor_model' filename='libgazebo_motor_model.so'>
        <robotNamespace/>
        <jointName>rotor_5_joint</jointName>
        <linkName>rotor_5</linkName>
        <turningDirection>cw</turningDirection>
        <timeConstantUp>0.0125</timeConstantUp>
        <timeConstantDown>0.025</timeConstantDown>
        <maxRotVelocity>1500</maxRotVelocity>
        <motorConstant>8.54858e-06</motorConstant>
        <momentConstant>0.06</momentConstant>
        <commandSubTopic>/gazebo/command/motor_speed</commandSubTopic>
        <motorNumber>0</motorNumber>
        <rotorDragCoefficient>0.000806428</rotorDragCoefficient>
        <rollingMomentCoefficient>1e-06</rollingMomentCoefficient>
        <motorSpeedPubTopic>/motor_speed/0</motorSpeedPubTopic>
        <rotorVelocitySlowdownSim>10</rotorVelocitySlowdownSim>
      </plugin>
      <plugin name='groundtruth_plugin' filename='libgazebo_groundtruth_plugin.so'>
        <robotNamespace/>
      </plugin>
      <plugin name='magnetometer_plugin' filename='libgazebo_magnetometer_plugin.so'>
        <robotNamespace/>
        <pubRate>100</pubRate>
        <noiseDensity>0.0004</noiseDensity>
        <randomWalk>6.4e-06</randomWalk>
        <biasCorrelationTime>600</biasCorrelationTime>
        <magTopic>/mag</magTopic>
      </plugin>
      <plugin name='barometer_plugin' filename='libgazebo_barometer_plugin.so'>
        <robotNamespace/>
        <pubRate>50</pubRate>
        <baroTopic>/baro</baroTopic>
      </plugin>
      <plugin name='mavlink_interface' filename='libgazebo_mavlink_interface.so'>
        <robotNamespace/>
        <imuSubTopic>/imu</imuSubTopic>
        <magSubTopic>/mag</magSubTopic>
        <baroSubTopic>/baro</baroSubTopic>
        <mavlink_addr>INADDR_ANY</mavlink_addr>
        <mavlink_udp_port>14560</mavlink_udp_port>
        <serialEnabled>0</serialEnabled>
        <serialDevice>/dev/ttyACM0</serialDevice>
        <baudRate>921600</baudRate>
        <qgc_addr>INADDR_ANY</qgc_addr>
        <qgc_udp_port>14550</qgc_udp_port>
        <sdk_addr>INADDR_ANY</sdk_addr>
        <sdk_udp_port>14540</sdk_udp_port>
        <hil_mode>0</hil_mode>
        <hil_state_level>0</hil_state_level>
        <enable_lockstep>1</enable_lockstep>
        <use_tcp>1</use_tcp>
        <motorSpeedCommandPubTopic>/gazebo/command/motor_speed</motorSpeedCommandPubTopic>
        <control_channels>
          <channel name='rotor0'>
            <input_index>0</input_index>
            <input_offset>0</input_offset>
            <input_scaling>1500</input_scaling>
            <zero_position_disarmed>0</zero_position_disarmed>
            <zero_position_armed>100</zero_position_armed>
            <joint_control_type>velocity</joint_control_type>
          </channel>
          <channel name='rotor1'>
            <input_index>1</input_index>
            <input_offset>0</input_offset>
            <input_scaling>1500</input_scaling>
            <zero_position_disarmed>0</zero_position_disarmed>
            <zero_position_armed>100</zero_position_armed>
            <joint_control_type>velocity</joint_control_type>
          </channel>
          <channel name='rotor2'>
            <input_index>2</input_index>
            <input_offset>0</input_offset>
            <input_scaling>1500</input_scaling>
            <zero_position_disarmed>0</zero_position_disarmed>
            <zero_position_armed>100</zero_position_armed>
            <joint_control_type>velocity</joint_control_type>
          </channel>
          <channel name='rotor3'>
            <input_index>3</input_index>
            <input_offset>0</input_offset>
            <input_scaling>1500</input_scaling>
            <zero_position_disarmed>0</zero_position_disarmed>
            <zero_position_armed>100</zero_position_armed>
            <joint_control_type>velocity</joint_control_type>
          </channel>
          <channel name='rotor4'>
            <input_index>4</input_index>
            <input_offset>0</input_offset>
            <input_scaling>1500</input_scaling>
            <zero_position_disarmed>0</zero_position_disarmed>
            <zero_position_armed>100</zero_position_armed>
            <joint_control_type>velocity</joint_control_type>
          </channel>
          <channel name='rotor5'>
            <input_index>5</input_index>
            <input_offset>0</input_offset>
            <input_scaling>1500</input_scaling>
            <zero_position_disarmed>0</zero_position_disarmed>
            <zero_position_armed>100</zero_position_armed>
            <joint_control_type>velocity</joint_control_type>
          </channel>
          <channel name='gimbal_roll'>
            <input_index>6</input_index>
            <input_offset>0</input_offset>
            <input_scaling>-3.1415</input_scaling>
            <zero_position_disarmed>0</zero_position_disarmed>
            <zero_position_armed>0</zero_position_armed>
            <joint_control_type>position_gztopic</joint_control_type>
            <gztopic>/gimbal_roll_cmd</gztopic>
            <joint_name>typhoon_h480::cgo3_camera_joint</joint_name>
          </channel>
          <channel name='gimbal_pitch'>
            <input_index>7</input_index>
            <input_offset>0</input_offset>
            <input_scaling>-3.1415</input_scaling>
            <zero_position_disarmed>0</zero_position_disarmed>
            <zero_position_armed>0</zero_position_armed>
            <joint_control_type>position_gztopic</joint_control_type>
            <gztopic>/gimbal_pitch_cmd</gztopic>
            <joint_name>typhoon_h480::cgo3_camera_joint</joint_name>
          </channel>
          <channel name='gimbal_yaw'>
            <input_index>8</input_index>
            <input_offset>0</input_offset>
            <input_scaling>-3.1415</input_scaling>
            <zero_position_disarmed>0</zero_position_disarmed>
            <zero_position_armed>0</zero_position_armed>
            <joint_control_type>position_gztopic</joint_control_type>
            <gztopic>/gimbal_yaw_cmd</gztopic>
            <joint_name>typhoon_h480::cgo3_vertical_arm_joint</joint_name>
          </channel>
          <channel name='left_leg'>
            <input_index>9</input_index>
            <input_offset>1</input_offset>
            <input_scaling>0.5</input_scaling>
            <zero_position_disarmed>0</zero_position_disarmed>
            <zero_position_armed>0</zero_position_armed>
            <joint_control_type>position</joint_control_type>
            <joint_control_pid>
              <p>3.5</p>
              <i>0.5</i>
              <d>0</d>
              <iMax>4</iMax>
              <iMin>-4</iMin>
              <cmdMax>6</cmdMax>
              <cmdMin>-6</cmdMin>
            </joint_control_pid>
            <joint_name>left_leg_joint</joint_name>
          </channel>
          <channel name='right_leg'>
            <input_index>10</input_index>
            <input_offset>1</input_offset>
            <input_scaling>0.5</input_scaling>
            <zero_position_disarmed>0</zero_position_disarmed>
            <zero_position_armed>0</zero_position_armed>
            <joint_control_type>position</joint_control_type>
            <joint_control_pid>
              <p>3.5</p>
              <i>0.5</i>
              <d>0</d>
              <iMax>4</iMax>
              <iMin>-4</iMin>
              <cmdMax>6</cmdMax>
              <cmdMin>-6</cmdMin>
            </joint_control_pid>
            <joint_name>right_leg_joint</joint_name>
          </channel>
        </control_channels>
      </plugin>
      <static>0</static>
      <plugin name='gazebo_imu_plugin' filename='libgazebo_imu_plugin.so'>
        <robotNamespace/>
        <linkName>typhoon_h480/imu_link</linkName>
        <imuTopic>/imu</imuTopic>
        <gyroscopeNoiseDensity>0.0003394</gyroscopeNoiseDensity>
        <gyroscopeRandomWalk>3.8785e-05</gyroscopeRandomWalk>
        <gyroscopeBiasCorrelationTime>1000.0</gyroscopeBiasCorrelationTime>
        <gyroscopeTurnOnBiasSigma>0.0087</gyroscopeTurnOnBiasSigma>
        <accelerometerNoiseDensity>0.004</accelerometerNoiseDensity>
        <accelerometerRandomWalk>0.006</accelerometerRandomWalk>
        <accelerometerBiasCorrelationTime>300.0</accelerometerBiasCorrelationTime>
        <accelerometerTurnOnBiasSigma>0.196</accelerometerTurnOnBiasSigma>
      </plugin>
      <plugin name='gimbal_controller' filename='libgazebo_gimbal_controller_plugin.so'>
        <joint_yaw>typhoon_h480::cgo3_vertical_arm_joint</joint_yaw>
        <joint_roll>typhoon_h480::cgo3_horizontal_arm_joint</joint_roll>
        <joint_pitch>typhoon_h480::cgo3_camera_joint</joint_pitch>
        <control_gimbal_channels>
          <channel>
            <joint_control_pid>
              <p>0.6</p>
              <i>0.1</i>
              <d>0.02</d>
              <iMax>0</iMax>
              <iMin>0</iMin>
              <cmdMax>1.0</cmdMax>
              <cmdMin>-1.0</cmdMin>
            </joint_control_pid>
            <joint_axis>joint_yaw</joint_axis>
          </channel>
          <channel>
            <joint_control_pid>
              <p>0.8</p>
              <i>0.035</i>
              <d>0.02</d>
              <iMax>0</iMax>
              <iMin>0</iMin>
              <cmdMax>0.3</cmdMax>
              <cmdMin>-0.3</cmdMin>
            </joint_control_pid>
            <joint_axis>joint_roll</joint_axis>
          </channel>
          <channel>
            <joint_control_pid>
              <p>2.068</p>
              <i>0.01245</i>
              <d>0.01</d>
              <iMax>0</iMax>
              <iMin>0</iMin>
              <cmdMax>0.3</cmdMax>
              <cmdMin>-0.3</cmdMin>
            </joint_control_pid>
            <joint_axis>joint_pitch</joint_axis>
          </channel>
        </control_gimbal_channels>
        <gimbal_imu>camera_imu</gimbal_imu>
        <robotNamespace>/</robotNamespace>
      </plugin>
      <plugin name='p3d_base_controller' filename='libgazebo_ros_p3d.so'>
        <alwaysOn>1</alwaysOn>
        <updateRate>50.0</updateRate>
        <bodyName>base_link</bodyName>
        <topicName>/prometheus/ground_truth/p300_basic</topicName>
        <gaussianNoise>0.00</gaussianNoise>
        <frameName>world</frameName>
        <xyzOffsets>0 0 0</xyzOffsets>
        <rpyOffsets>0 0 0</rpyOffsets>
        <robotNamespace>/</robotNamespace>
      </plugin>
      <pose frame=''>0 0 0.46 0 -0 0</pose>
    </model>
    <state world_name='autonomous_landing'>
      <sim_time>449 984000000</sim_time>
      <real_time>450 726444363</real_time>
      <wall_time>1719732418 78313900</wall_time>
      <iterations>112496</iterations>
      <model name='ground_plane'>
        <pose frame=''>0 0 0 0 -0 0</pose>
        <scale>1 1 1</scale>
        <link name='link'>
          <pose frame=''>0 0 0 0 -0 0</pose>
          <velocity>0 0 0 0 -0 0</velocity>
          <acceleration>0 0 0 0 -0 0</acceleration>
          <wrench>0 0 0 0 -0 0</wrench>
        </link>
      </model>
      <model name='logo_ground'>
        <pose frame=''>0 0 0 0 -0 0</pose>
        <scale>1 1 1</scale>
        <link name='logo_ground::link'>
          <pose frame=''>0 0 0.01 0 -0 0</pose>
          <velocity>0 0 0 0 -0 0</velocity>
          <acceleration>0 0 0 0 -0 0</acceleration>
          <wrench>0 0 0 0 -0 0</wrench>
        </link>
      </model>
      <model name='typhoon_h480'>
        <pose frame=''>-2.01026 1.02961 3.49365 0.001462 0.000997 0.0007</pose>
        <scale>1 1 1</scale>
        <link name='base_link'>
          <pose frame=''>-2.01026 1.02961 3.49365 0.001462 0.000997 0.0007</pose>
          <velocity>0.008744 -0.009403 0 0.001485 0.004118 -0.000299</velocity>
          <acceleration>-0.008097 -0.006832 -0.003474 0.135936 -0.176823 -0.008666</acceleration>
          <wrench>-0.016355 -0.0138 -0.007018 0 -0 0</wrench>
        </link>
        <link name='cgo3_camera_link'>
          <pose frame=''>-1.90558 1.02994 3.44636 -0.000127 0.724387 0.000684</pose>
          <velocity>0.007951 -0.009278 0.000168 0.001217 -0.001097 0.000126</velocity>
          <acceleration>0.01714 0.012521 -0.007478 0.082969 -0.088708 0.001254</acceleration>
          <wrench>0.001714 0.001252 -0.000748 0 -0 0</wrench>
        </link>
        <link name='cgo3_horizontal_arm_link'>
          <pose frame=''>-2.01026 1.02986 3.49365 -9.5e-05 0.000996 0.000768</pose>
          <velocity>0.008744 -0.009348 1e-06 0.001213 0.004117 0.000125</velocity>
          <acceleration>0.004622 0.007486 -0.010893 0.083036 -0.177006 0.001268</acceleration>
          <wrench>0.000462 0.000749 -0.001089 0 -0 0</wrench>
        </link>
        <link name='cgo3_mount_link'>
          <pose frame=''>-2.01026 1.02961 3.49365 0.001462 0.000997 0.0007</pose>
          <velocity>0.008744 -0.009403 0 0.001484 0.004118 -0.000301</velocity>
          <acceleration>0.018966 0.014363 -0.010905 0.136025 -0.176951 -0.009105</acceleration>
          <wrench>0.001897 0.001436 -0.00109 0 -0 0</wrench>
        </link>
        <link name='cgo3_vertical_arm_link'>
          <pose frame=''>-2.01026 1.02961 3.49365 0.001462 0.000996 0.000768</pose>
          <velocity>0.008744 -0.009392 0 0.001485 0.004117 0.000125</velocity>
          <acceleration>0.018962 0.014211 -0.010906 0.136033 -0.176965 0.001215</acceleration>
          <wrench>0.001896 0.001421 -0.001091 0 -0 0</wrench>
        </link>
        <link name='gps::link'>
          <pose frame=''>-2.01026 1.02961 3.49365 0.001462 0.000997 0.0007</pose>
          <velocity>0.008744 -0.009403 0 0.001485 0.004118 -0.000299</velocity>
          <acceleration>-0.00969 -0.008048 -0.003653 0.136031 -0.176955 -0.008337</acceleration>
          <wrench>-0.000145 -0.000121 -5.5e-05 0 -0 0</wrench>
        </link>
        <link name='left_leg'>
          <pose frame=''>-2.01026 1.02961 3.49365 0.001465 0.000997 0.0007</pose>
          <velocity>0.008744 -0.009393 -8e-06 0.001273 0.004118 -0.000299</velocity>
          <acceleration>0.025825 0.022278 -0.024451 0.149225 -0.176945 -0.008349</acceleration>
          <wrench>0.002582 0.002228 -0.002445 0 -0 0</wrench>
        </link>
        <link name='right_leg'>
          <pose frame=''>-2.01026 1.02961 3.49365 0.001462 0.000997 0.0007</pose>
          <velocity>0.008744 -0.009403 0 0.001484 0.004118 -0.000299</velocity>
          <acceleration>0.028141 0.020119 0.015811 0.136022 -0.176954 -0.008336</acceleration>
          <wrench>0.002814 0.002012 0.001581 0 -0 0</wrench>
        </link>
        <link name='rotor_0'>
          <pose frame=''>-2.21966 1.1521 3.57626 -0.001671 -0.000621 -2.9028</pose>
          <velocity>0.009121 -0.009463 0.001044 -0.070917 0.111309 2.52569</velocity>
          <acceleration>-0.023281 -0.017538 -0.024053 0.546645 -0.62296 1.08628</acceleration>
          <wrench>-0.000116 -8.8e-05 -0.00012 0 -0 0</wrench>
        </link>
        <link name='rotor_1'>
          <pose frame=''>-1.7987 0.909871 3.57549 -0.001746 0.000198 -2.4254</pose>
          <velocity>0.009045 -0.009588 -0.001049 0.071102 -0.09706 1.16345</velocity>
          <acceleration>-0.025171 -0.020943 0.017508 1.26205 1.03648 2.51756</acceleration>
          <wrench>-0.000126 -0.000105 8.8e-05 0 -0 0</wrench>
        </link>
        <link name='rotor_2'>
          <pose frame=''>-2.21949 0.906577 3.5759 -0.001162 -0.001318 2.89745</pose>
          <velocity>0.009046 -0.009462 0.000679 0.073684 -0.100693 -2.58378</velocity>
          <acceleration>-0.025265 -0.017491 -0.057432 2.77047 1.16002 2.83541</acceleration>
          <wrench>-0.000126 -8.7e-05 -0.000287 0 -0 0</wrench>
        </link>
        <link name='rotor_3'>
          <pose frame=''>-1.79887 1.14939 3.57584 0.0008 -0.001591 1.69928</pose>
          <velocity>0.009118 -0.009588 -0.000692 -0.068375 0.107519 -1.22751</velocity>
          <acceleration>-0.023236 -0.020989 0.050063 -0.904295 1.07676 -1.25585</acceleration>
          <wrench>-0.000116 -0.000105 0.00025 0 -0 0</wrench>
        </link>
        <link name='rotor_4'>
          <pose frame=''>-2.01223 1.27219 3.57623 0.00069 0.001617 -0.563771</pose>
          <velocity>0.009157 -0.009525 0.000368 0.0726 -0.09924 2.57627</velocity>
          <acceleration>-0.022277 -0.019264 0.028996 3.02954 0.461661 -1.85556</acceleration>
          <wrench>-0.000111 -9.6e-05 0.000145 0 -0 0</wrench>
        </link>
        <link name='rotor_5'>
          <pose frame=''>-2.01189 0.786779 3.57552 0.001771 0.000206 0.478883</pose>
          <velocity>0.009009 -0.009524 -0.000354 -0.069402 0.109401 -2.31446</velocity>
          <acceleration>-0.026199 -0.01917 -0.036987 -1.16551 0.449601 -0.265736</acceleration>
          <wrench>-0.000131 -9.6e-05 -0.000185 0 -0 0</wrench>
        </link>
        <link name='typhoon_h480/imu_link'>
          <pose frame=''>-2.01026 1.02961 3.49365 0.001462 0.000997 0.0007</pose>
          <velocity>0.008744 -0.009403 0 0.001484 0.004118 -0.000299</velocity>
          <acceleration>-0.00969 -0.008048 -0.003653 0.136023 -0.176955 -0.008337</acceleration>
          <wrench>-0.000145 -0.000121 -5.5e-05 0 -0 0</wrench>
        </link>
      </model>
      <light name='sun'>
        <pose frame=''>0 0 10 0 -0 0</pose>
      </light>
    </state>
    <gui fullscreen='0'>
      <camera name='user_camera'>
        <pose frame=''>-1.822 -4.59623 9.97426 -0 1.03964 1.0962</pose>
        <view_controller>orbit</view_controller>
        <projection_type>perspective</projection_type>
      </camera>
    </gui>
  </world>
</sdf>
